Workbook
Name Activity: Cuesheet!$G$16:$G$233
Name Activity: #REF!
Name Content: 'Digital Content'!$B$1:$H$50
Name TYPE: Cuesheet!#REF!
Name TYPE: #REF!

Sheet Cuesheet
A1: 2025 Concacaf Nations League Finals _ INFT Script | H1: =VLOOKUP(C4,'Match Database '!$A:$G,2,FALSE) -> 45739 | L1: FINAL VERSION _1:44PM
C3: Match # | F3: 1 -Team A | G3: 1 - Team B | H3: Venue
C4: THIRD PLACE | E4: Warmup | F4: =VLOOKUP(C4,'Match Database '!$A:$G,6,FALSE) -> 🇨🇦Canada (CAN) | G4: =VLOOKUP(C4,'Match Database '!$A:$G,7,FALSE) -> 🇺🇸 USA (USA) | H4: =VLOOKUP(C4,'Match Database '!$A:$G,5,FALSE) -> SOFI
C5: KICK OFF: | D5: =B72 -> 0.625 | F5: =VLOOKUP(C4,'Match Database '!$A:$G,4,FALSE) -> 0.625 | G5: GATES: | H5: =VLOOKUP(C4,'Match Database '!$A:$G,3,FALSE) -> 0.58333333
A7: Wired Camera 1: Presenters
A8: Wired Camera 2: Grayson - DJ
A9: RF Camera 3: Najjah
D10: =IF($F$5-$B$72>=0,TEXT(ABS($F$5-$B$72),"-mm:ss"),TEXT(ABS($F$5-$B$72),"+mm:ss")) -> +00:00 | H10: `
A11: 2nd Match | B11: Match # | C11: 1 -Team A | D11: 1 - Team B | G11: ACTIVITY | H11: AUDIO | I11: Video Board | J11: LED Ribbons | K11: Script ENG | L11: Script SPANISH
B12: FINAL | C12: =VLOOKUP(B12,'Match Database '!$A:$G,6,FALSE) -> 🇲🇽 Mexico (MEX) | D12: =VLOOKUP(B12,'Match Database '!$A:$G,7,FALSE) -> 🇵🇦 Panama (PAN) | F12: Digital Content | G12: CNLF Generic Animation | H12: =VLOOKUP(G12,'Digital Content'!$C:$L,6,0) -> x | I12: =VLOOKUP(G12,'Digital Content'!$C:$L,7,0) -> x | J12: =VLOOKUP(G12,'Digital Content'!$C:$L,8,0) -> 0 | K12: =VLOOKUP(G12,'Digital Content'!$C:$L,9,0) -> x | L12: =VLOOKUP(G12,'Digital Content'!$C:$L,10,0) -> x
B13: KICK OFF: | C13: =VLOOKUP(B12,'Match Database '!$A:$G,4,FALSE) -> 0.77083333 | F13: Sponsors: | G13: Qatar Airways Still | H13: =VLOOKUP(G13,Sponsors!$A:$H,3,0) -> #N/A | I13: =VLOOKUP(G13,Sponsors!$A:$H,4,0) -> #N/A | J13: =VLOOKUP(G13,Sponsors!$A:$H,5,0) -> #N/A | K13: =VLOOKUP(G13,Sponsors!$A:$H,7,0) -> #N/A
C14: =IF($C$13-$B$207>=0,TEXT(ABS($C$13-$B$207),"-mm:ss"),TEXT(ABS($C$13-$B$207),"+mm:ss")) -> +00:00 | D14: =D119 -> 0 | E14: Warmup | H14: Video board + LED: | I14: Ann_Starting XI | J14: Starting XI LED
B15: TIME OF DAY | C15: ZERO | D15: Minute | E15: Second | F15: DURATION | G15: ACTIVITY | H15: AUDIO | I15: Video Board | J15: LED Ribbons | K15: Script ENG | L15: Script SPANISH
A16: 1 | B16: =$H$5 -> 0.58333333 | C16: =$F$5-B16 -> 0.041666667 | F16: 0 | G16: GATES OPEN | H16: BGM | I16: CNLF GENERIC | J16: Generic LED
A17: =A16+1 -> 2 | B17: =B16+F16 -> 0.58333333 | C17: =C16-F16 -> 0.041666667 | D17: 30 | E17: 0 | F17: =TIME(0,D17,E17) -> 0.020833333 | G17: SOFI protected Time. | H17: BGM | I17: CNLF GENERIC | J17: Generic LED
A18: =A17+1 -> 3 | B18: =B17+F17 -> 0.60416667 | C18: =C17-F17 -> 0.020833333 | F18: =TIME(0,D18,E18) -> 0
A19: =A18+1 -> 4 | B19: =B18+F18 -> 0.60416667 | C19: =C18-F18 -> 0.020833333 | D19: 1 | E19: 30 | F19: =TIME(0,D19,E19) -> 0.0010416667 | G19: Big Welcome + Band | H19: ANN mics | I19: RF Cams | J19: Generic LED | K19: Duda: Welcome everyone to the CONCACAF Nations League Finals at Sofi Stadium, intro today's game, THIRD PLACE MATCH… It's gonna be a party and I am not alone. Intro Ili. Ili: Bienvenidos a los juegos finales de CONCACAF Nations League en SoFi Stadium! El primer partido para el tercer lugar sera entre Canada y Estados Unidos. Esto va a ser una fiesta y estamos listos para vivirla. Duda: That's right Ili, but we need some moves, we need some energy and becaue of that, ladies and gentlemen let me introduce you to the life of the party, the Mister Zoom Zoom! Najja: Najja introduces himself and Grayson Duda: wraps it up
A20: =A19+1 -> 5 | B20: =B19+F19 -> 0.60520833 | C20: =C19-F19 -> 0.019791667 | F20: =TIME(0,D20,E20) -> 0
A21: =A20+1 -> 6 | B21: =B20+F20 -> 0.60520833 | C21: =C20-F20 -> 0.019791667 | D21: 1 | F21: =TIME(0,D21,E21) -> 0.00069444444 | G21: Players' warm-up | H21: BGM | I21: CF/RF | J21: Generic LED
A22: =A21+1 -> 7 | B22: =B21+F21 -> 0.60590278 | C22: =C21-F21 -> 0.019097222 | F22: =TIME(0,D22,E22) -> 0
A23: =A22+1 -> 8 | B23: =B22+F22 -> 0.60590278 | C23: =C22-F22 -> 0.019097222 | F23: =TIME(0,D23,E23) -> 0 | G23: Sponsors: Pre match 1
A24: =A23+1 -> 9 | B24: =B23+F23 -> 0.60590278 | C24: =C23-F23 -> 0.019097222 | E24: 15 | F24: =TIME(0,D24,E24) -> 0.00017361111 | G24: Rexona Still (Unilever) | H24: =VLOOKUP(G24,Sponsors!$A:$H,3,0) -> PA+BGM | I24: Rexona Still | J24: Rexona | K24: Rexona, the official antiperspirant partner of the 2025 Concacaf Nations League Finals. You Bring The Heat, Rexona Brings the 72 hour Non-stop protection. | L24: Rexona, el antitranspirante oficial de la Final de la Liga de Naciones de Concacaf 2025. Tú pones la pasión, Rexona la protección.
A25: =A24+1 -> 10 | B25: =B24+F24 -> 0.60607639 | C25: =C24-F24 -> 0.018923611 | E25: 15 | F25: =TIME(0,D25,E25) -> 0.00017361111 | G25: Valvoline Still | H25: =VLOOKUP(G25,Sponsors!$A:$H,3,0) -> PA+BGM | I25: =VLOOKUP(G25,Sponsors!$A:$H,4,0) -> Valvoline Still | J25: =VLOOKUP(G25,Sponsors!$A:$H,5,0) -> Valvoline | K25: Valvoline products are a game changer for your vehicle's performance. Pick up your favorite Valvoline product today at your local O'Reilly Auto Parts and score superior engine protection for miles ahead. Valvoline and O'Reilly Auto Parts. Proud sponsors of the CONCACAF Nations League. | L25: Aumenta el desempeño de tu vehículo y gana la jugada con Valvoline. Encuentra tu producto favorito Valvoline en tu tienda local O'Reilly Auto Parts y consigue una defensa superior para tu motor. Valvoline y O'Reilly Auto Parts, orgullosos patrocinadores de la CONCACAF Nations League
A26: =A25+1 -> 11 | B26: =B25+F25 -> 0.60625 | C26: =C25-F25 -> 0.01875 | E26: 15 | F26: 0.00017361111 | G26: Galaxy Still | H26: =VLOOKUP(G26,Sponsors!$A:$H,3,0) -> PA+BGM | I26: Galaxy Still | J26: Generic LED | K26: GALAXY FANS…SECURE YOUR SEATS FOR 20-25'S BIGGEST MATCHES WITH THE “CHAMPIONS PACK"! CELEBRATE THE GALAXY'S SIXTH STAR WITH A GAME FOR EVERY STAR…ALL AT A DISCOUNTED RATE! TO SECURE YOUR SEATS, VISIT “L-A GALAXY DOT COM SLASH TICKETS”.
A27: =A26+1 -> 12 | B27: =B26+F26 -> 0.60642361 | C27: =C26-F26 -> 0.018576389 | E27: 15 | F27: 0.00017361111 | G27: LA Sports Commision | H27: =VLOOKUP(G27,Sponsors!$A:$H,3,0) -> PA+BGM | I27: LA Sports Commission Still | J27: Generic LED | K27: As we countdown to the 2026 FIFA World Cup, the Los Angeles World Cup Host Committee is proud to unveil the Official Los Angeles poster. The poster will be prominently featured around the region leading up to the U.S. Men’s National Team Opening Match - right here at SoFi Stadium. To learn more about Los Angeles as a FIFA World Cup Host City visit Los Angeles FWC 26 Dot Com
A28: =A27+1 -> 13 | B28: =B27+F27 -> 0.60659722 | C28: =C27-F27 -> 0.018402778 | E28: 30 | F28: =TIME(0,D28,E28) -> 0.00034722222 | G28: Riyadh Air Still | H28: =VLOOKUP(G28,Sponsors!$A:$H,3,0) -> PA+BGM | I28: Riyadh Air Still | J28: Riyadh Air | K28: Riyadh (Ri-ah-de) Air is proud to be the official airline of the 2025 Concacaf Nations League Finals. The partnership brings together two ambitious, like-minded organizations who share a commitment to excellence, whether in the skies or on the pitch
A29: =A28+1 -> 14 | B29: =B28+F28 -> 0.60694444 | C29: =C28-F28 -> 0.018055556 | E29: 15 | F29: =TIME(0,D29,E29) -> 0.00017361111 | G29: Shriners Children Still | H29: PA+BGM | I29: Shriners Children still | J29: Shriners Children | K29: Shriners Children’s is the official children’s healthcare provider of the Concacaf Nations League Finals and provides life-changing care, regardless of the ability to pay or insurance status. Shriners Children’s — the most amazing care anywhere
A30: =A29+1 -> 15 | B30: =B29+F29 -> 0.60711806 | C30: =C29-F29 -> 0.017881944 | E30: 15 | F30: =TIME(0,D30,E30) -> 0.00017361111 | G30: MOLTEN Still | H30: =VLOOKUP(G30,Sponsors!$A:$H,3,0) -> PA+BGM | I30: =VLOOKUP(G30,Sponsors!$A:$H,4,0) -> Molten Still | J30: =VLOOKUP(G30,Sponsors!$A:$H,5,0) -> Molten | K30: Molten, the official match ball of the 2025 Concacaf Nations League Finals
A31: =A30+1 -> 16 | B31: =B30+F30 -> 0.60729167 | C31: =C30-F30 -> 0.017708333 | E31: 15 | F31: =TIME(0,D31,E31) -> 0.00017361111 | G31: Neau Water Still | H31: =VLOOKUP(G31,Sponsors!$A:$H,3,0) -> PA+Audio File from DJ | I31: =VLOOKUP(G31,Sponsors!$A:$H,4,0) -> Neau Water Still | J31: =VLOOKUP(G31,Sponsors!$A:$H,5,0) -> Neau Water
A32: =A31+1 -> 17 | B32: =B31+F31 -> 0.60746528 | C32: =C31-F31 -> 0.017534722 | E32: 15 | F32: =TIME(0,D32,E32) -> 0.00017361111 | G32: PIF Still | H32: =VLOOKUP(G32,Sponsors!$A:$H,3,0) -> PA+BGM | I32: PIF Still | J32: Generic LED | K32: PIF is a proud partner of the 2025 Concacaf Nations League Finals. Committed to elevating youth and unlocking opportunities to grow football at every level of the game in North America, Central America and the Caribbean while focusing on PIF’s four sponsorship pillars – Inclusivity, Sustainability, Youth and Technology.
A33: =A32+1 -> 18 | B33: =B32+F32 -> 0.60763889 | C33: =C32-F32 -> 0.017361111 | E33: 15 | F33: =TIME(0,D33,E33) -> 0.00017361111 | G33: Underdog Still | H33: PA+BGM | I33: Underdog Still | J33: Generic LED | K33: The four big North American nations are back in action and soccer fans from all over the US are playing along on Underdog. Just pick higher or lower on your favorite player’s stats like goals, assists, and clean sheets to win up to 1000x your money. Millions of fans from all over the US have won over $1bn on Underdog. Sign up for Underdog today using promo code: NATIONSLEAGUE and you’ll get a Free Pick PLUS up to $1000 in bonus credit when you deposit. <disclaimer, read fast>: Must be 18+ and present in California. Terms apply. See underdogfantasy.com/rules/promotions for details. Concerned with your play? Call 1-800-GAMBLER or visit www.ncpgambling.org.
A34: =A33+1 -> 19 | B34: =B33+F33 -> 0.6078125 | C34: =C33-F33 -> 0.0171875 | F34: =TIME(0,D34,E34) -> 0
A35: =A34+1 -> 20 | B35: =B34+F34 -> 0.6078125 | C35: =C34-F34 -> 0.0171875 | D35: 1 | F35: =TIME(0,D35,E35) -> 0.00069444444 | G35: Line-Up CANADA: Visual only (Starting XI, head coach, Substitutes) | H35: BGM | I35: GFX | J35: Generic LED
A36: =A35+1 -> 21 | B36: =B35+F35 -> 0.60850694 | C36: =C35-F35 -> 0.016493056 | E36: 10 | F36: =TIME(0,D36,E36) -> 0.00011574074 | G36: CAN_ALFONSO DAVIES | H36: SOT | I36: Anti-discrimination VT | J36: WWIW
A37: =A36+1 -> 22 | B37: =B36+F36 -> 0.60862269 | C37: =C36-F36 -> 0.016377315 | D37: 1 | F37: =TIME(0,D37,E37) -> 0.00069444444 | G37: Line-Up USA: Visual only (Starting XI, head coach, Substitutes) | H37: BGM | I37: GFX | J37: Generic LED
A38: =A37+1 -> 23 | B38: =B37+F37 -> 0.60931713 | C38: =C37-F37 -> 0.01568287 | E38: 10 | F38: =TIME(0,D38,E38) -> 0.00011574074 | G38: USA_TYLER ADAMS | H38: SOT | I38: Anti-discrimination VT | J38: WWIW
A39: =A38+1 -> 24 | B39: =B38+F38 -> 0.60943287 | C39: =C38-F38 -> 0.01556713 | E39: 30 | F39: =TIME(0,D39,E39) -> 0.00034722222 | G39: Rexona VT | H39: VT AUDIO | I39: Rexona VT | J39: Rexona
A40: =A39+1 -> 25 | B40: =B39+F39 -> 0.60978009 | C40: =C39-F39 -> 0.015219907 | E40: 30 | F40: =TIME(0,D40,E40) -> 0.00034722222 | G40: Shriners Children VT | H40: VT Audio | I40: Shriners Children VT | J40: Shriners Children
A41: =A40+1 -> 26 | B41: =B40+F40 -> 0.61012731 | C41: =C40-F40 -> 0.014872685 | E41: 30 | F41: =TIME(0,D41,E41) -> 0.00034722222 | G41: MOLTEN Video | H41: =VLOOKUP(G41,Sponsors!$A:$H,3,0) -> VT Audio | I41: =VLOOKUP(G41,Sponsors!$A:$H,4,0) -> Molten Video | J41: =VLOOKUP(G41,Sponsors!$A:$H,5,0) -> Molten
A42: =A41+1 -> 27 | B42: =B41+F41 -> 0.61047454 | C42: =C41-F41 -> 0.014525463 | E42: 30 | F42: =TIME(0,D42,E42) -> 0.00034722222 | G42: Aramco Video | H42: =VLOOKUP(G42,Sponsors!$A:$H,3,0) -> VT Audio | I42: =VLOOKUP(G42,Sponsors!$A:$H,4,0) -> Aramco Video | J42: =VLOOKUP(G42,Sponsors!$A:$H,5,0) -> Aramco
...

Sheet In Match Script
A1: SCRIPT BOOK: IN MATCH SCRIPT
A3: COMPETITION SCRIPT
A4: ITEM | B4: CODE | C4: ENGLISH | D4: SPANISH
A5: C - 12 | B5: GOAL Team | C5: Goal for [Team] | D5: Gol para [equipo]
A6: C-12.1 | B6: GOAL Player | C6: Goal scored by Player number….Player name for {Team} | D6: Gol anotado por el jugador Numero __, jugador ___…de [equipo]
A7: C - 13 | B7: OWN GOAL | C7: (if it is an own goal the player shall not be mentioned:) Own goal scored in favour of [Team] | D7: (si es un gol en propia puerta, no se mencionará al jugador :) Gol en propia puerta a favor de [Team]
A8: C - 14 | B8: SUB 1 | C8: Substitution for [Team] Player number [Number], [Name of outgoing player according to the start list] Is replaced by player number [Number], [Name of incoming player according to the start list] | D8: Cambio de [Team] jugador numero [Número], [Nombre del jugador saliente según la lista de inicio] Es reemplazado por el jugador número [Número], [Nombre del jugador entrante de acuerdo con la lista de inicio]
A9: C - 15 | B9: SUB 2: concussion | C9: Suspected concussion substitution for (team) Player Number (number), (Name of outgoing player according to start list) Is replaced by player number (number), (Name of incoming player according to start list) This substitution is prioritising player welfare and is an approved additional substitution per team | D9: Sustitución por sospecha de conmoción cerebral para (equipo) Número de jugador (número), (Nombre del jugador saliente según la lista de inicio) Es reemplazado por el número de jugador (número), (Nombre del jugador entrante según la lista de inicio) Esta sustitución prioriza el bienestar del jugador y es una sustitución adicional aprobada por equipo.
A10: C - 17 | B10: YELLOW CARD | C10: Yellow card for Player number [Number], [Name], from [Team] | D10: Tarjeta amarilla para el jugador número [Número], [Nombre], de [Equipo]
A11: C - 18 | B11: DOUBLE YELLOW CARD | C11: Second yellow card for Player number [Number], [Name], from [Team] | D11: Segunda tarjeta amarilla para el jugador número [Número], [Nombre], de [Equipo]
A12: C - 19 | B12: RED CARD | C12: Red card for Player number [Number], [Name], from [Team] | D12: Tarjeta roja para el jugador número [Número], [Nombre], de [Equipo]
A13: C - 21 | B13: SCORE 1 HALF TIME | C13: Ladies and gentlemen, the score at the end of the first half is [Number] [Team A] and [Number] [Team B] | D13: Damas y caballeros, el marcador al final de la primera mitad es [Número] [Equipo A] y [Número] [Equipo B]
A14: C - 22 | B14: SCORE 2 FULL TIME | C14: Ladies and gentlemen,(TODAY/TONIGHTS) the final score is [Number] [Team A] - [Number] [Team B] | D14: Damas y caballeros, (HOY / ESTA NOCHE) el marcador final es [Número] [Equipo A] - [Número] [Equipo B]
A15: C - 23 | B15: ATTENDANCE 1 | C15: LADIES AND GENTLEMEN, THE TOTAL ATTENDANCE FOR TODAY'S/TONIGHT'S MATCH IS __________. WE WANT TO SAY THANK YOU TO ALL FANS ATTENDING THE 2024 Concacaf W Gold Cup PRELIMS/ GROUP STAGE/QUARTERFINALS/SEMI-FINALS/FINAL.] | D15: DAMAS Y CABALLEROS, LA ASISTENCIA TOTAL PARA EL PARTIDO DE HOY / ESTA NOCHE ES __________. QUEREMOS DAR LAS GRACIAS A TODOS LOS FANS QUE ASISTIERON A LA FASE DE GRUPO DE LA COPA _____ / CUARTOS DE FINAL / SEMIFINALES / FINAL.
... A21: C - 29 | B21: PENALTY KICKS 2 for M4 and M7: no extra time as these matches are played directly before the semi-finals and final | C21: Ladies and gentlemen, since the match is level at the end of normal playing time, kicks from the penalty mark will be taken to determine the winner. | D21: Damas y caballeros, dado que el partido está empatado al final del tiempo regular, se ejecutarán tiros desde el punto penal para determinar el ganador.
A23: ANTI DISCRIMINATION 3-STEP PROTOCOL
A24: ITEM # | B24: CODE | C24: ENGLISH | D24: Spanish
A25: A - 1 | B25: PROACTIVE STADIUM MESSAGE | C25: Fair play and mutual respect are fundamental to football. Discriminatory behaviour is not permitted. We ask you to uphold the principles of fair play and to take part in football in a spirit of unity, respect and equality | D25: El juego limpio y el respeto mutuo son fundamentales para el fútbol. No se permite el comportamiento discriminatorio. Le pedimos que defienda los principios del juego limpio y participe en el fútbol con un espíritu de unidad, respeto e igualdad.
A26: A - 2 | B26: REACTIVE STADIUM MESSAGE | C26: Attention, please! This is an important announcement: we urge you to stop all discriminatory chants and gestures. We ask all to uphold the principles of fair play and to take part in football in a spirit of unity, respect and equality. Thank you. | D26: ¡Atención por favor! Este es un anuncio importante: le instamos a que detenga todos los cánticos y gestos discriminatorios. Pedimos a todos que defiendan los principios del juego limpio y participen en el fútbol con un espíritu de unidad, respeto e igualdad. Gracias.
A27: A - 3 | B27: 3 STEP PROCEDURE - STEP 1 (stop the match) | C27: Attention, please! This is an important announcement. The referee has indicated that he/she may have to suspend the match because of discriminatory behaviour amongst spectators. Discrimination in football stadiums will not be tolerated. If this continues, the game will be suspended, and may be abandoned. Thank you. | D27: ¡Atención por favor! Este es un anuncio importante. El árbitro ha indicado que puede suspender el partido debido a comportamientos discriminatorios entre los espectadores. No se tolerará la discriminación en los estadios de fútbol. Si esto continúa, el juego se suspenderá y es posible que se abandone. Gracias.
A28: A - 4 | B28: 3 STEP PROCEDURE - STEP 2 (suspend the match) | C28: Attention, please! This is an important announcement. Because of continuing discriminatory behaviour amongst spectators, the match has been suspended and the teams will now return to their dressing rooms. We remind you once again that discrimination in football stadiums will not be tolerated. If discriminatory behaviour amongst the spectators continues, then the match will be abandoned. We repeat that this match will be abandoned if there is continuing discriminatory behaviour amongst spectators. Thank you. | D28: ¡Atención por favor! Este es un anuncio importante. Debido al continuo comportamiento discriminatorio entre los espectadores, el partido ha sido suspendido y los equipos ahora regresarán a sus vestuarios. Les recordamos una vez más que no se tolerará la discriminación en los estadios de fútbol. Si continúa el comportamiento discriminatorio entre los espectadores, se abandonará el partido. Repetimos que este partido será abandonado si persiste el comportamiento discriminatorio entre los espectadores. Gracias.
A29: A - 5 | B29: 3 STEP PROCEDURE - STEP 3 (abandon the match) A) If the abandoned match would be followed by another match in the same stadium | C29: Attention, please! This is an important security announcement. We regret to inform you that, because of continuing discriminatory behaviour amongst spectators which is interfering with the game, the referee has decided to abandon the match. We repeat: this match has been abandoned. All spectators are now requested to leave the stadium in an orderly fashion. In the interests of safety, all spectators are also asked to take their time when leaving the ground and to follow the instructions of the stewards and security personnel. Further statements on the consequences of the abandonment of the match will be made by Concacaf on its website as soon as possible. | D29: ¡Atención por favor! Este es un anuncio de seguridad importante. Lamentamos informarle que, debido al comportamiento discriminatorio continuo entre los espectadores que están interfiriendo con el juego, el árbitro ha decidido abandonar el partido. Repetimos: este partido ha sido abandonado. Ahora se pide a todos los espectadores que abandonen el estadio de forma ordenada. En aras de la seguridad, también se pide a todos los espectadores que se tomen su tiempo al abandonar el terreno y que sigan las instrucciones de los acomodadores y de personal de seguridad. Concacaf hará más declaraciones sobre las consecuencias del abandono del partido en su sitio web lo antes posible.
A32: C - 3 | B32: LINE UPS 1 | C32: AND NOW, LADIES AND GENTLEMEN, TODAY'S STARTING LINE-UPS FOR (TEAM/COUNTRY). For [Team A] Number [#], [NAME] Number [#], [NAME] Number [#], [NAME] etc... The Coach is, [NAME], For [Team B] Number [#], [NAME] Number [#], [NAME] Number [#], [NAME] etc... The Coach is, [NAME], | D32: Y AHORA, SEÑORAS Y CABALLEROS, LA ALINEACIÓN INICIAL DE HOY PARA (EQUIPO / PAÍS). Para [Equipo A] Número [#], [NOMBRE] Número [#], [NOMBRE] Número [#], [NOMBRE], etc. El entrenador es, [NOMBRE], Para [Equipo B] Número [#], [NOMBRE] Número [#], [NOMBRE] Número [#], [NOMBRE], etc. El entrenador es, [NOMBRE],

Sheet Sponsors
A1: CONCACAF NATIONS LEAGUE Sponsors Tracker | K1: Sponsors Blocks
K2: Pre-match 1 | L2: Pre-match 2 | M2: half-Time | N2: Post Match | O2: Check
A3: Sponsor | B3: Duration | C3: Audio | D3: Video Board | E3: LED Ribbons | F3: Pitchside LED | G3: Script | H3: # per match | I3: Notes
A4: Valvoline Still | B4: 0.010416667 | C4: PA+BGM | D4: Valvoline Still | E4: Valvoline | F4: Valvoline | G4: Valvoline knows the best players never stop running. And that’s exactly what Valvoline does– provides maximum protection to keep your vehicle performing at its best. Find Valvoline full synthetic motor oils at your local O’Reilly Auto Parts. Proud partner of the CONCACAF Nations League Finals. Valvoline sabe que los mejores jugadores nunca dejan de correr. Y eso es exactamente lo que hace Valvoline Ofrece máxima protección para mantener su vehículo funcionando al máximo rendimiento Encuentra los aceites de motor totalmente sintéticos de Valvoline en su tienda local O’Reilly Auto Parts .Orgulloso socio de la Copa Oro Femenina | H4: 1 | I4: English and spanish | K4: 1
A5: Valvoline - LOCAL MECHANICS RECOGNITION | B5: 0.041666667 | C5: PA+BGM | D5: LIVE | E5: Valvoline | F5: Valvoline
A6: Valvoline Video | B6: 0.020833333 | C6: VT Audio | D6: Valvoline Video | E6: Valvoline | F6: Valvoline | H6: 1 | I6: English and spanish | K6: 1
A7: Rexona Still (Unilever) | B7: 0.010416667 | C7: PA+BGM | D7: Rexona Still | E7: Rexona | F7: Rexona | H7: 2 | K7: 1 | M7: 1
A8: Rexona VT | B8: 0.020833333 | C8: VT Audio | D8: Rexona VT | E8: Rexona | F8: Rexona
A9: Dove Video (Uniliever) | B9: 0.020833333 | C9: VT Audio | D9: Dove Video | E9: Dove | F9: Dove | H9: 2 | L9: 1 | N9: 1
A10: Degree Still (Unilever) | B10: 0.010416667 | C10: PA+BGM | D10: Degree Still | E10: Degree | F10: Degree | H10: 2 | L10: 1 | N10: 1
A11: Degree Video (Unilever) | B11: 0.020833333 | C11: Vt Audio | D11: Degree Video | E11: Degree | F11: Degree | H11: 2 | K11: 1 | M11: 1
A12: MOLTEN Still | B12: 0.010416667 | C12: PA+BGM | D12: Molten Still | E12: Molten | F12: Molten | G12: Molten, the official match ball of 2024 ConcacafNations League Final | H12: 4 | K12: 1 | L12: 1 | M12: 1 | N12: 1
A13: MOLTEN Video | B13: 0.020833333 | C13: VT Audio | D13: Molten Video | E13: Molten | F13: Molten | H13: 4 | K13: 1 | L13: 1 | M13: 1 | N13: 1
A14: Aramco Still | B14: 0.010416667 | C14: PA+BGM | D14: Aramco Still | E14: Aramco | F14: Aramco | H14: 4 | K14: 1 | L14: 1 | M14: 1 | N14: 1
A15: Aramco Video | B15: 0.020833333 | C15: VT Audio | D15: Aramco Video | E15: Aramco | F15: Aramco | H15: 4 | K15: 1 | L15: 1 | M15: 1 | N15: 1
A16: Neau Water Still | B16: 0.010416667 | C16: PA+Audio File from DJ | D16: Neau Water Still | E16: Neau Water | F16: Neau Water | G16: Finally a water that's different. No more aggressive filtration and additives to mask the taste.neaūwater’s proprietary technology (H.A.R.T.) restores water to its natural form, giving you pureH20 with neutral pH and clean, crisp taste. Experience the difference atneauwater.com. Find us atAmazon.com. Welcome back, water! | H16: 1 | K16: 1
A17: Neau Water Video | B17: 0.020833333 | C17: VT Audio | D17: Neau Water Video | E17: Neau Water | F17: Neau Water | H17: 1 | M17: 1
A18: Chilis Fan Cam | B18: 0.020833333 | C18: PA+BGM | D18: Chili's Still | E18: Chilis | F18: Chilis | H18: 1 | M18: 1
A19: Body Armour Video +PA | B19: 0.020833333 | C19: PA+BGM | D19: Body Armour Video | E19: Body Armour | F19: Body Armour | G19: BODYARMOR Sports Drink is your go-to hydration source all season long. With real ingredients,electrolytes, antioxidants and no artificial sweeteners, flavors, or dyes, BODYARMOR Sports Drink willtake yourgame to the next level. Reach for real hydration with BODYARMOR Sports Drink. Nothing is more real | H19: 2 | I19: video with no audio | K19: 1 | M19: 1
A20: PIF Still | B20: 0.010416667 | C20: PA+BGM | H20: 2 | K20: 1 | M20: 1
A21: PIF Video | B21: 0.020833333 | C21: VT Audio | D21: PIF Video | H21: 2 | K21: 1 | M21: 1
A22: Riyadh Air Still | B22: 0.010416667 | C22: PA+BGM | H22: 2 | L22: 1 | M22: 1
A23: Riyadh Video | B23: 0.020833333 | C23: VT Audio | D23: Riyadh Video | H23: 2 | L23: 1 | M23: 1
A24: STA - Visit Saudi Still | B24: 0.010416667 | C24: PA+BGM | H24: 4 | K24: 1 | L24: 1 | M24: 1 | N24: 1
A25: STA - Visit Saudi | B25: 0.020833333 | C25: VT Audio | D25: STA - Visit Saudi Video | H25: 4 | K25: 1 | L25: 1 | M25: 1 | N25: 1
A26: El Mayor Tequila Still - TBC | B26: 0.010416667 | C26: PA+BGM | H26: 1 | K26: 1
A27: El Mayor Tequila Video - TBC | B27: 0.020833333 | C27: VT Audio | H27: 1 | L27: 1
A28: Shriners Children Still | B28: 0.010416667 | C28: PA+BGM
A29: Shriners Children VT | B29: 0.020833333 | C29: VT Audio
A30: FIFA World Cup 2026 | B30: 0.020833333 | C30: VT Audio
A31: Paramount+ (CBS) | B31: 0.020833333 | C31: VT Audio
A32: Underdog Still | B32: 0.010416667 | C32: PA+BGM
A33: Underdog VT | B33: 0.020833333 | C33: BGM
A34: Macron VT | B34: 0.020833333 | C34: VT Audio
A35: Galaxy Still | B35: 0.010416667 | C35: PA+BGM
A36: LA Sports Commision | B36: 0.010416667 | C36: PA+BGM

Sheet Digital Content
F2: MAIN VB | G2: RIBBON BOARDS | Q2: EXTRA | T2: Fieldboards | V2: LE | X2: Notes
B3: CONCACAF NATIONS LEAGUE DIGITAL CONTENT LIST | E3: Name | F3: Diamon-Vision Center Hung | G3: Lower Silver Endzone | H3: Lower Silver Endzone | I3: Lower Silver Sideline | J3: Vomitory Gaps Boards | K3: Upper Sideline | L3: Upper End Zone | M3: HOF Ribbon North Side | N3: HOF Ribbon East EZ | O3: HOF Ribbon South Side | P3: HOF Ribbon West EZ | Q3: AT&T Live effects Board | R3: PEPSI Board | S3: Miller Boards | T3: Fieldboards | U3: Fieldboard Stage | V3: LED DJ Booth (LE) | X3: TGI Notes | Y3: Concacaf Notes | Z3: LE Notes
G4: w/o score strip | H4: with score strip
E5: Spec | F5: 1920x1080 | G5: 2496x48 | H5: 832x48 | I5: 11504x40 | J5: 496x104 | K5: 11248x48 | L5: 2496x48 | M5: 12000x48 | N5: 3840x48 | O5: 11940x48 | P5: 3900x48 | Q5: 3840x384 | R5: 1008x1064 | T5: 2 x 5,700 px (w) x 90 px (h) | U5: tbd | V5: tbd
D6: # of files | E6: Format | G6: will not use | J6: black out | Q6: cannot use - will remain ATT Stadium | S6: cannot use
J7: or DREAM IS NOW (ENG SPA)
A8: Department | B8: Campaign Number | C8: Campaign List | E8: TYPE | AC8: Type | AD8: Minute | AE8: Second | AF8: Duration | AG8: AUDIO | AH8: Video Board | AI8: LED Ribbons
A9: 01-Brand | C9: CNLF Generic Animation | D9: 8 | E9: Animated | F9: x | H9: x | I9: x | K9: x | L9: x | R9: x | T9: x | V9: x | AC9: VT | AD9: 1 | AE9: 30 | AF9: =TIME(0,AD9,AE9) -> 0.0010416667 | AG9: Audio VT | AH9: =AC9+"_"+TIME(0,AD9,AE9) -> #VALUE!
A10: 01-Brand | C10: CNLF Titleboard | E10: Animated | T10: x | X10: added titleboard 3.5.24
A11: 01-Brand | C11: The Dream is NOW (ENG SPA) | D11: 10 | E11: Animated | J11: X | K11: x | L11: x | M11: x | N11: x | O11: x | P11: x | R11: x | T11: x | V11: x
A12: 01-Brand | C12: Hashtag Loop | D12: 7 | E12: Animated | F12: x | H12: x | I12: x | K12: x | L12: x | T12: x | V12: x
A13: 01-Brand | C13: Match Up Animation (USA v PAN) | D13: 12 | E13: Animated | F13: x | H13: x | I13: x | K13: x | L13: x | M13: x | N13: x | O13: x | P13: x | R13: x | T13: x | V13: x
A14: 01-Brand | C14: Match Up Animation (CAN v MEX) | D14: 12 | E14: Animated | F14: x | H14: x | I14: x | K14: x | L14: x | M14: x | N14: x | O14: x | P14: x | R14: x | T14: x | V14: x
A15: 01-Brand | C15: Match Up Animation (Third Place) | D15: 12 | E15: Animated | F15: x | H15: x | I15: x | K15: x | L15: x | M15: x | N15: x | O15: x | P15: x | R15: x | T15: x | V15: x
A16: 01-Brand | C16: Match Up Animation (FINAL) | D16: 12 | E16: Animated | F16: x | H16: x | I16: x | K16: x | L16: x | M16: x | N16: x | O16: x | P16: x | R16: x | T16: x | V16: x
A17: 01-Brand | C17: Match Up Still (taken from Animation) | D17: 12 | E17: Static | F17: x | H17: x | I17: x | K17: x | L17: x | M17: x | N17: x | O17: x | P17: x | R17: x | T17: x | V17: x
A18: 01-Brand | C18: Replay Wipe x 1 (:02) | D18: 1 | E18: Animated | F18: x
A19: 01-Brand | C19: Starting XI (PAN) | D19: 5 | E19: Animated | F19: x | H19: x | I19: x | K19: x | L19: x
A20: 01-Brand | C20: Starting XI (MEX) | D20: 5 | E20: Animated | F20: x | H20: x | I20: x | K20: x | L20: x
A21: 01-Brand | C21: Starting XI (USA) | D21: 5 | E21: Animated | F21: x | H21: x | I21: x | K21: x | L21: x
A22: 01-Brand | C22: Starting XI (CAN) | D22: 5 | E22: Animated | F22: x | H22: x | I22: x | K22: x | L22: x
A23: 01-Brand | C23: Subsitutes (PAN) | D23: 1 | E23: Animated | F23: x
A24: 01-Brand | C24: Subsitutes (MEX) | D24: 1 | E24: Animated | F24: x
A25: 01-Brand | C25: Subsitutes (USA) | D25: 1 | E25: Animated | F25: x
A26: 01-Brand | C26: Subsitutes (CAN) | D26: 1 | E26: Animated | F26: x
A27: 01-Brand | C27: Goal Animation (generic) | D27: 10 | E27: Animated | F27: x | H27: x | I27: x | K27: x | L27: x | M27: x | N27: x | O27: x | P27: x | V27: x
A28: 01-Brand | C28: Substitution (generic ) | D28: 1 | E28: Static | F28: x
A29: 01-Brand | C29: Anti Discrimination - What's Wrong is Wrong ENG | D29: 10 | E29: Animated | F29: x | H29: x | I29: x | K29: x | L29: x | M29: x | N29: x | O29: x | P29: x | T29: x
A30: 01-Brand | C30: Anti Discrimination - What's Wrong is Wrong SPA | D30: 10 | E30: Animated | F30: x | H30: x | I30: x | K30: x | L30: x | M30: x | N30: x | O30: x | P30: x | T30: x
A31: 01-Brand | C31: Thunderstruck Hype Reel (LE to provide) SF/3RD/FINAL | D31: 3 | E31: Video | F31: x | X31: LiveEngine to provide
A32: 01-Brand | C32: DJ loop LED tier (LE to provide) | D32: 2 | E32: Animated | H32: x | I32: x | K32: x | L32: x | M32: x | N32: x | O32: x | P32: x | X32: LiveEngine to provide
B33: Brand | C33: 1hr To KO | D33: 1 | E33: Video | F33: x
B34: Brand | C34: TEAM VIDEO (USA) | D34: 1 | E34: Video | F34: x
B35: Brand | C35: TEAM VIDEO (CAN) | D35: 1 | E35: Video | F35: x
B36: Brand | C36: TEAM VIDEO (PAN) | D36: 1 | E36: Video | F36: x
B37: Brand | C37: TEAM VIDEO (MEX) | D37: 1 | E37: Video | F37: x
B38: Brand | C38: TEAM HEADSHOTS (USA) | D38: 23 | E38: Video | F38: x
B39: Brand | C39: TEAM HEADSHOTS (CAM) | D39: 23 | E39: Video | F39: x
B40: Brand | C40: TEAM HEADSHOTS (PAN) | D40: 23 | E40: Video | F40: x
B41: Brand | C41: TEAM HEADSHOTS (MEX) | D41: 23 | E41: Video | F41: x
...

Sheet Full Script
A1: SCRIPT BOOK: 2024 Concacaf W Gold Cup
A3: COMPETITION SCRIPT
A4: ITEM | B4: CODE | C4: ENGLISH | D4: SPANISH
A5: C - 1 | B5: Welcome | C5: Ladies and gentlemen, welcome to [Venue] for today's match of the 2024 Concacaf W Gold Cup [Team A] and [Team B] | D5: Damas y caballeros, bienvenidos a [Sede] para el partido de hoy de la COPA ORO W DE CONCACAF entre [Equipo A] y [Equipo B]
A6: C - 2 | B6: Warm ups | C6: LADIES AND GENTLEMEN, PLEASE WELCOME THE NATIONAL TEAM OF TEAM A / TEAM B! | D6: DAMAS Y CABALLEROS, ¡DEMOS LA BIENVENIDA AL EQUIPO NACIONAL DE [EQUIPO A] / [EQUIPO B]!
A7: C - 3 | B7: LINE UPS 1 | C7: AND NOW, LADIES AND GENTLEMEN, TODAY'S STARTING LINE-UPS FOR (TEAM/COUNTRY). For [Team A] Number [#], [NAME] Number [#], [NAME] Number [#], [NAME] etc... The Coach is, [NAME], For [Team B] Number [#], [NAME] Number [#], [NAME] Number [#], [NAME] etc... The Coach is, [NAME], | D7: Y AHORA, SEÑORAS Y CABALLEROS, LA ALINEACIÓN INICIAL DE HOY PARA (EQUIPO / PAÍS). Para [Equipo A] Número [#], [NOMBRE] Número [#], [NOMBRE] Número [#], [NOMBRE], etc. El entrenador es, [NOMBRE], Para [Equipo B] Número [#], [NOMBRE] Número [#], [NOMBRE] Número [#], [NOMBRE], etc. El entrenador es, [NOMBRE],
A8: C - 4 | B8: OFFICIALS WELCOME 1 | C8: The referee for this match is [NAME] from [RefCountry] The assistant referees are [NAME] from [AR1Country] and [NAME] from [AR2Country] The fourth official is [NAME] from [FourthCountry] | D8: El árbitro de este partido es [NAME] de [RefCountry] Los árbitros asistentes son [NAME] de [AR1Country] y [NAME] de [AR2Country] El cuarto árbitro es [NOMBRE] de [FourthCountry]
A9: C - 5 | B9: VAR OFFICIALS WELCOME 2 | C9: The Video Assisant referee for this match is [Name] from [RefCountry] The Assistant Video Assisant referees are [VAR1] from [VAR1Country] and [VAR2] from [VAR2Country] | D9: El árbitro asistente de video para este partido es [Nombre] de [RefCountry] Los árbitros del asistente de video asistente son [VAR1] de [VAR1 Country] y [VAR2] de [VAR2 Country]
A10: C - 6 | B10: TEAM FOP 1 | C10: Let's Welcome the National teams of [Team A] and [Team B] | D10: "Demos la bienvenida a los equipos nacionales del [Equipo A] y [Equipo B]
A11: C - 7 | B11: NATIONAL ANTHEMS | C11: LADIES AND GENTLEMEN, PLEASE RISE FOR THE NATIONAL ANTHEM OF TEAM A/TEAM B. | D11: DAMAS Y CABALLEROS, POR FAVOR LEVANTARSE POR EL HIMNO NACIONAL DEL EQUIPO A / EQUIPO B.
A12: C - 8 | B12: COUNTDOWN TO KICKOFF | C12: LET'S COUNTDOWN TOGETHER… 10…9…8…7…6…5…4…3…2…1!!!! LET'S GO !!! | D12: HAGAMOS LA CUENTA REGRESIVA JUNTOS ... 10… 9… 8… 7… 6… 5… 4… 3… 2… 1 !!!! VAMOS !!!
A13: C - 9 | B13: CONCACAFPRES | C13: Ladies and gentlemen, please welcome the CONCACAF President …. and [Name 2nd highest ranked dignitary], accompanied by members of the CONCACAF Football Family. | D13: Damas y caballeros, den la bienvenida al presidente de CONCACAF…. y [Nombre del segundo dignatario de mayor rango], acompañado por miembros de la Familia del Fútbol de CONCACAF.
A14: C - 10 | B14: CONCACAFPRES SPEECH | C14: Ladies and gentlemen, please welcome the CONCACAF President, VICTOR MONTAGLIANI to make a brief speech. | D14: Damas y caballeros, den la bienvenida al Presidente de CONCACAF, VICTOR MONTAGLIANI quien dara un breve discurso.
A15: C - 11 | B15: LOC DIGNITARY SPEECH | C15: And now, please welcome [Name of dignitary] who will also make a brief speech. | D15: Y ahora, denle la bienvenida a [Nombre del dignatario], quien también hará un breve discurso.
A16: C - 12 | B16: GOAL Team | C16: Goal for [Team] | D16: Gol para [equipo]
B17: GOAL Player | C17: Goal scored by Player number….Player name | D17: Gol anotado por Numero del jugador…nombre del jugador
A18: C - 13 | B18: OWN GOAL | C18: (if it is an own goal the player shall not be mentioned:) Own goal scored in favour of [Team] | D18: (si es un gol en propia puerta, no se mencionará al jugador :) Gol en propia puerta a favor de [Team]
A19: C - 14 | B19: SUB 1 | C19: Substitution for [Team] Player number [Number], [Name of outgoing player according to the start list] Is replaced by player number [Number], [Name of incoming player according to the start list] | D19: Cambio de [Team] jugador numero [Número], [Nombre del jugador saliente según la lista de inicio] Es reemplazado por el jugador número [Número], [Nombre del jugador entrante de acuerdo con la lista de inicio]
A20: C - 15 | B20: SUB 2: concussion | C20: Suspected concussion substitution for (team) Player Number (number), (Name of outgoing player according to start list) Is replaced by player number (number), (Name of incoming player according to start list) This substitution is prioritising player welfare and is an approved additional substitution per team | D20: Sustitución por sospecha de conmoción cerebral para (equipo) Número de jugador (número), (Nombre del jugador saliente según la lista de inicio) Es reemplazado por el número de jugador (número), (Nombre del jugador entrante según la lista de inicio) Esta sustitución prioriza el bienestar del jugador y es una sustitución adicional aprobada por equipo.
A21: C - 16 | B21: MOMENT OF SILENCE | C21: Ladies and gentlemen, we kindly ask you to stand to observe a moment of silence in memory of [reason]. Thank you. | D21: Señoras y señores, les rogamos que se pongan de pie para guardar un momento de silencio en memoria de [la razón]. Gracias.
A22: C - 17 | B22: YELLOW CARD | C22: Yellow card for Player number [Number], [Name], from [Team] | D22: Tarjeta amarilla para el jugador número [Número], [Nombre], de [Equipo]
A23: C - 18 | B23: DOUBLE YELLOW CARD | C23: Second yellow card for Player number [Number], [Name], from [Team] | D23: Segunda tarjeta amarilla para el jugador número [Número], [Nombre], de [Equipo]
A24: C - 19 | B24: RED CARD | C24: Red card for Player number [Number], [Name], from [Team] | D24: Tarjeta roja para el jugador número [Número], [Nombre], de [Equipo]
A25: C - 20 | B25: YOUTH PROGRAMME | C25: Ladies and Gentlemen, the children participating in the Youth Programme for the 2024 Concacaf W Gold Cup have been selected by (Sponsor ?) and the Local Organizing Committee. | D25: Damas y caballeros, los niños que participan en el Programa Juvenil de la COPA ORO 2021 DE CONCACAF han sido seleccionados por (¿sponsor?) Y el Comité Organizador Local.
A26: C - 21 | B26: SCORE 1 HALF TIME | C26: Ladies and gentlemen, the score at the end of the first half is [Number] [Team A] and [Number] [Team B] | D26: Damas y caballeros, el marcador al final de la primera mitad es [Número] [Equipo A] y [Número] [Equipo B]
A27: C - 22 | B27: SCORE 2 FULL TIME | C27: Ladies and gentlemen,(TODAY/TONIGHTS) the final score is [Number] [Team A] - [Number] [Team B] | D27: Damas y caballeros, (HOY / ESTA NOCHE) el marcador final es [Número] [Equipo A] - [Número] [Equipo B]
A28: C - 23 | B28: ATTENDANCE 1 | C28: LADIES AND GENTLEMEN, THE TOTAL ATTENDANCE FOR TODAY'S/TONIGHT'S MATCH IS __________. WE WANT TO SAY THANK YOU TO ALL FANS ATTENDING THE 2024 Concacaf W Gold Cup PRELIMS/ GROUP STAGE/QUARTERFINALS/SEMI-FINALS/FINAL.] | D28: DAMAS Y CABALLEROS, LA ASISTENCIA TOTAL PARA EL PARTIDO DE HOY / ESTA NOCHE ES __________. QUEREMOS DAR LAS GRACIAS A TODOS LOS FANS QUE ASISTIERON A LA FASE DE GRUPO DE LA COPA _____ / CUARTOS DE FINAL / SEMIFINALES / FINAL.
A29: C - 24 | B29: ATTENDANCE 2 (If the attendance figure at half time confirms the full turnout) | C29: Ladies and gentlemen, the total attendance for this match is [Number]. Congratulations on being part of a full stadium tonight in [Venue]. | D29: Damas y caballeros, la asistencia total a este partido es [Número]. Felicitaciones por ser parte de un estadio lleno esta noche en [Sede].
... A37: C - 32 | B37: FINAL MATCH | C37: On behalf of CONCACAFand the Local Organising ON BEHALF OF CONCACAF, THE LOCAL ORGANIZING COMMITTEE AND _______STADIUM, WE WOULD LIKE TO EXTEND OUR SINCERE THANKS TO ALL FANS AND ACKNOWLEDGE OUR OUTSTANDING PARTNERS (BIMBO, BMO, GATORADE, GRUPO MONGE, MDOELO, PREDATOR, QATAR AIRWAYS, SAL LA FINA, SITE ONE, TOYOTA, UNILEVER, AND VALVOLINE YOU HAVE BEEN GREAT FANS THROUGHOUT OUT THE TOURNAMENT AND WE HOPE YOU HAVE FOND MEMORIES OF The 2024 Concacaf W Gold Cup TOURNAMENT! THANK YOU AND GET HOME SAFELY!! | D37: En nombre de CONCACAF y la Organización Local EN NOMBRE DE CONCACAF, EL COMITÉ ORGANIZADOR LOCAL Y EL ESTADIO SOFI NOS GUSTARÍA EXTENDER NUESTRO SINCERO AGRADECIMIENTO A TODOS LOS FANS Y RECONOCEMOS A NUESTROS SOCIOS DESTACADOS (BIMBO, BMO, GATORADE, GRUPO MONGE, MDOELO, PREDATOR, QATAR AIRWAYS, SAL LA FINA, SITE ONE, TOYOTA, UNILEVER, AND VALVOLINE ¡HAS SIDO GRANDES FANS DURANTE TODO EL TORNEO Y ESPERAMOS QUE TENGAS FONDOS RECUERDOS DE LA COPA ______! GRACIAS Y LLEGUE A CASA SEGURO !!
A39: HOUSEKEEPING SCRIPT
A40: ITEM # | B40: CODE | C40: ENGLISH | D40: Spanish
A41: H - 1 | B41: WELCOME 1 MOMENTS AWAY | C41: GOOD AFTERNOON/EVENING LADIES AND GENTLEMEN, AND WELCOME TO THE 2024 Concacaf W Gold Cup TOURNAMENT. CONCACAF WELCOMES ALL FANS OF INTERNATIONAL SOCCER TO TODAY'S MATCH/DOUBLE HEADER/MATCH BETWEEN (TEAM A) AND (TEAM B). | D41: BUENAS TARDES / NOCHES DAMAS Y CABALLEROS, Y BIENVENIDOS AL TORNEO _______F. CONCACAF DA LA BIENVENIDA A TODOS LOS FANÁTICOS DEL FÚTBOL INTERNACIONAL AL PARTIDO / JORNADA DOBLE / PARTIDO DE HOY ENTRE (EQUIPO A) Y (EQUIPO B).
A42: H - 2 | B42: WELCOME 2 MOMENTS AWAY | C42: Ladies and gentleman, as the start of the next match is just moments away, we kindly ask you to return to your seats. The upcoming match is [Team A] and [Team B]. | D42: Damas y caballeros, como el comienzo del próximo partido está a solo unos minutos, les pedimos que regresen a sus asientos. El próximo partido es [Equipo A] y [Equipo B].
A43: H - 3 | B43: SEATING | C43: As the [Stadium] is an assigned seating stadium, you are required to sit in the seat shown on the ticket. Please ask a security steward for asisstance. | D43: Como el [Estadio] es un estadio con asientos asignados, debe sentarse en el asiento que se muestra en el boleto. Favor pida ayuda a un delegado de seguridad.
A44: H - 4 | B44: FOP | C44: We would like to remind all spectators that access to the pitch is prohibited and will result in prosecution. | D44: Nos gustaría recordar a todos los espectadores que el acceso al terreno de juego está prohibido y dará lugar a un proceso judicial.
A45: H - 5 | B45: TOBACCO-FREE EVENT | C45: Welcome to a Tobacco-Free2024 Concacaf W Gold Cup. The use of tobacco products and e-cigarettes is NOT permitted in the stadium, except in the designated smoking areas. Please refrain from smoking in all other areas. | D45: Bienvenido a la COPA_______ sin tabaco. El uso de productos de tabaco y cigarrillos electrónicos NO está permitido en el estadio, excepto en las áreas designadas para fumar. Abstenerse de fumar en todas las demás áreas.
A46: H - 6 | B46: STANDING | C46: All stairways are emergency evacuation routes and MUST be kept clear at all times. Persistent standing during the game is DANGEROUS and spoils the view of the person behind. Please respect fellow spectators. | D46: Todas las escaleras son rutas de evacuación de emergencia y DEBEN mantenerse despejadas en todo momento. Permanecer de pie durante el juego es PELIGROSO y estropea la vista de la persona que está detrás. Respete a los demás espectadores.
A47: H - 7 | B47: HAVE YOUR TICKETS | C47: Please carry your ticket with you at all times. You will need it to access your assigned seating areas. No pass outs are available at this venue. | D47: Por favor lleve su boleto con usted en todo momento. Lo necesitará para acceder a sus áreas de asientos asignadas. No hay pases disponibles en este lugar.
A48: H - 8 | B48: FLASH PHOTOGRAPHY | C48: Please be advised that flash photography is not permitted within [Venue], As a courtesy to the players, please turn off the flash on your camera. | D48: Tenga en cuenta que no se permite la fotografía con flash dentro de [Lugar]. Como cortesía para los jugadores, apague el flash de su cámara.
A49: H - 9 | B49: HOT WEATHER | C49: Ladies and gentlemen, please look after yourself in the hot weather by keeping hydrated and using plenty of sunscreen. | D49: Damas y caballeros, cuídense en el clima caluroso manteniéndose hidratados y usando abundante protector solar.
...

Sheet Match Database 
A1: Match | B1: Date | C1: Gates | D1: KO Local Time | E1: Venue | F1: Team A | G1: Team B | H1: City
A2: SF 1 | B2: 45736 | C2: 0.625 | D2: 0.66666667 | E2: SOFI | F2: 🇺🇸 USA (USA) | G2: 🇵🇦 Panama (PAN) | H2: Los Angeles
A3: SF2 | B3: 45736 | C3: 0.77083333 | D3: 0.8125 | E3: SOFI | F3: 🇨🇦Canada (CAN) | G3: 🇲🇽 Mexico (MEX) | H3: Los Angeles
A4: THIRD PLACE | B4: 45739 | C4: 0.58333333 | D4: 0.625 | E4: SOFI | F4: 🇨🇦Canada (CAN) | G4: 🇺🇸 USA (USA) | H4: Los Angeles
A5: FINAL | B5: 45739 | C5: 0.72916667 | D5: 0.77083333 | E5: SOFI | F5: 🇲🇽 Mexico (MEX) | G5: 🇵🇦 Panama (PAN) | H5: Los Angeles

Sheet VAR CODE
B2: VAR CHECK/REVIEW | E2: VAR OUTCOME
E3: DECISION CONFIRMED | F3: # | G3: CHANGE OF DECISION | H3: #
B5: GOAL GIVEN | C5: CHECKING GOAL | D5: A | G5: NO GOAL | OFFSIDE | H5: 41
C6: CHECKING FOR OFFSIDE | D6: 1 | G6: NO GOAL | FOUL | H6: 42
C7: CHECKING FOR FOUL | D7: 2 | E7: GOAL CONFIRMED | F7: 31 | G7: NO GOAL | HANDBALL | H7: 43
C8: CHECKING FOR HANDBALL | D8: 3 | G8: NO GOAL | BALL OUT OF PLAY | H8: 54
C9: CHECKING FOR BALL OUT OF PLAY | D9: 4
B11: GOAL NOT GIVEN | C11: CHECKING GOAL | D11: A | G11: GOAL AWARDED | NO OFFSIDE | H11: 45
C12: CHECKING OFFSIDE | D12: 5 | G12: GOAL AWARDED | NO FOUL | H12: 56
C13: CHECKING FOUL | D13: 6 | E13: NO GOAL CONFIRMED | F13: 32 | G13: GOAL AWARDED | NO HANDBALL | H13: 47
C14: CHECKING HANDBALL | D14: 7 | G14: GOAL AWARDED | BALL NOT OUT OF PLAY | H14: 58
C15: CHECKING BALL OUT OF PLAY | D15: 8
B17: PENALTY GIVEN | C17: CHECKING PENALTY | D17: B
C18: CHECKING FOUL | D18: 9 | E18: PENALTY CONFIRMED | F18: 33 | G18: NO PENALTY | H18: 49
C19: CHECKING HANDBALL | D19: 10
C20: CHECKING FOUL INSIDE OR OUTSIDE AREA | D20: 11
C21: CHECKING POSSIBLE OFFSIDE | D21: 12
C22: CHECKING HANDBALL INSIDE OR OUTSIDE AREA | D22: 13
C23: CHECKING POSSIBLE OFFENCE LEADING UP TO PENALTY | D23: 14
C24: CHECKING POSSIBLE BALL OUT OF PLAY | D24: 15
B26: PENALTY NOT GIVEN | C26: CHECKING POSSIBLE PENALTY | D26: C
C27: POSSIBLE PENALTY | CHECKING FOUL | D27: 16 | E27: NO PENALTY CONFIRMED | F27: 34 | G27: PENALTY AWARDED | H27: 50
C28: POSSIBLE PENALTY | CHECKING HANDBALL | D28: 17
C29: POSSIBLE PENALTY | CHECKING FOUL OUTSIDE AREA | D29: 18
C30: POSSIBLE PENALTY | CHECKING HANDBALL OUTSIDE AREA | D30: 19
C31: CHECKING OFFENCE LEADING UP TO POSSIBLE PENALTY | D31: 20
B33: ENCROACHMENT | C33: PENALTY KICK SCENARIO 1 – goal allowed | E33: PENALTY KICK SCENARIO 1 – goal allowed
C34: CHECKING FOR ENCROACHMENT | D34: 21 | E34: GOAL CONFIRMED | F34: 35 | G34: PENALTY RETAKE | H34: 51
C35: CHECKING FOR OFFENCE BY KICKER | D35: 22
C36: PENALTY KICK SCENARIO 2 – missed or saved | E36: PENALTY KICK SCENARIO 2 – missed or saved
C37: CHECKING FOR ENCROACHMENT | D37: 21 | E37: NO RETAKE | F37: 52 | G37: PENALTY RETAKE | H37: 61
C38: CHECKING FOR OFFENCE BY GK | D38: 23
C39: PENALTY KICK SCENARIO 3 – goal disallowed | E39: PENALTY KICK SCENARIO 3 – goal disallowed
C40: CHECKING ENCROACHMENT | D40: 21 | E40: NO GOAL CONFIRMED | F40: 36 | G40: GOAL AWARDED | H40: 55
C41: CHECKING OFFENCE BY KICKER | D41: 25 | G41: PENALTY RETAKE
B43: RED CARD GIVEN / NOT GIVEN | C43: CHECKING POSSIBLE INCORRECT DISMISSAL | D43: 26 | E43: RED CARD CONFIRMED | F43: 37 | G43: NO RED CARD | H43: 62
C44: CHECKING FOR POSSIBLE RED CARD | D44: 27
B46: MISTAKEN IDENTITY | C46: CHECKING FOR POSSIBLE MISTAKEN IDENTITY | D46: 28 | E46: DECISION CONFIRMED | F46: 38 | G46: MISTAKEN IDENTITY | H46: 63

Sheet National Anthems
A1: Country | B1: Group | C1: national anthem file name | D1: File length | E1: Actual Duration | F1: Anthem Code | H1: goal sting file name | I1: Duration
A2: 🇲🇽 Mexico (MEX) | C2: Mexico | D2: 0.063888889 | E2: 0.065277778 | F2: =C2&"_"&TEXT(D2,"hh:mm")&"/"&TEXT(E2,"hh:mm") -> Mexico_01:32/01:34
A3: 🇵🇦 Panama (PAN) | C3: Panama | D3: 0.059027778 | E3: 0.060416667 | F3: =C3&"_"&TEXT(D3,"hh:mm")&"/"&TEXT(E3,"hh:mm") -> Panama_01:25/01:27
A4: 🇺🇸 USA (USA) | C4: United States (USA) | D4: 0.050694444 | E4: 0.052083333 | F4: =C4&"_"&TEXT(D4,"hh:mm")&"/"&TEXT(E4,"hh:mm") -> United States (USA)_01:13/01:15
A5: Canada (CAN) | C5: Canada | F5: Canada (CAN)_01:16/01:19
